Workbook

Sheet Evaluation
A1: BUV AI TOOL EVALUATION TEMPLATE
C2: Tool name | D2: <Enter tool name> | E2: Evaluation date | F2: <Enter date>
C3: Requester | D3: <Enter information> | E3: Evaluator | F3: <Enter evaluator name>
C4: Requester Department | D4: <Enter information> | E4: Conclusion | F4: JOINT (ICT + Committee)
B6: ICT Director Sign-off | C6: <Date / Signature>
B7: AI Governance Committee Chair Sign-off | C7: <Date / Signature>
B8: Joint Decision Required | C8: YES (both signatures required)
B9: Escalation on Disagreement | C9: Refer to Joint Review Board (Guideline §9)
B10: Total score | C10: =SUM(F13:F36) | D10: High criteria count | E10: =COUNTIF(F13:F36,3) | F10: Critical High | G10: =COUNTIFS(G13:G36,"CRITICAL",F13:F36,3) -> 0
A12: ID | B12: Category | C12: Criteria | D12: Description | E12: Risk level | F12: Score | G12: Critical | H12: Notes | I12: Information source
A13: 1 | B13: Data & Privacy | C13: Data retention / training | D13: Does the tool use input data to train the model? | G13: CRITICAL
A14: 2 | B14: Data & Privacy | C14: Data residency | D14: Where is data stored/processed? | F14: =IF(E10="Low (1)",1,IF(E10="Medium (2)",2,IF(E10="High (3)",3,"")))
A15: 3 | B15: Data & Privacy | C15: Data classification fit | D15: Is it compatible with BUV's data classification levels? | F15: =IF(E11="Low (1)",1,IF(E11="Medium (2)",2,IF(E11="High (3)",3,""))) | G15: CRITICAL
A16: 4 | B16: Security | C16: Authentication | D16: What level of SSO/MFA is supported? | F16: =IF(E12="Low (1)",1,IF(E12="Medium (2)",2,IF(E12="High (3)",3,""))) | G16: CRITICAL
A17: 5 | B17: Security | C17: Access control | D17: Does it have RBAC / admin control / central management? | F17: =IF(E13="Low (1)",1,IF(E13="Medium (2)",2,IF(E13="High (3)",3,""))) | G17: CRITICAL
A18: 6 | B18: Security | C18: Audit logging | D18: Does it have logging, audit trail and monitoring? | F18: =IF(E14="Low (1)",1,IF(E14="Medium (2)",2,IF(E14="High (3)",3,"")))
A19: 7 | B19: Model Governance | C19: Explainability | D19: Level of model transparency / explainability | F19: =IF(E15="Low (1)",1,IF(E15="Medium (2)",2,IF(E15="High (3)",3,"")))
A20: 8 | B20: Model Governance | C20: Version control | D20: Is there version control / model change management? | F20: =IF(E16="Low (1)",1,IF(E16="Medium (2)",2,IF(E16="High (3)",3,"")))
A21: 9 | B21: Model Governance | C21: Retraining policy | D21: Is there a clear update / retraining policy? | F21: =IF(E17="Low (1)",1,IF(E17="Medium (2)",2,IF(E17="High (3)",3,"")))
A22: 10 | B22: AI Risk & Ethics | C22: Bias & fairness | D22: Are there mechanisms to reduce bias / ensure fairness? | F22: =IF(E18="Low (1)",1,IF(E18="Medium (2)",2,IF(E18="High (3)",3,"")))
A23: 11 | B23: AI Risk & Ethics | C23: Hallucination risk | D23: What is the risk level of incorrect / fabricated / inaccurate output? | F23: =IF(E19="Low (1)",1,IF(E19="Medium (2)",2,IF(E19="High (3)",3,"")))
A24: 12 | B24: AI Risk & Ethics | C24: Safety & misuse | D24: Risk of misuse / prompt abuse / unsafe content | F24: =IF(E20="Low (1)",1,IF(E20="Medium (2)",2,IF(E20="High (3)",3,"")))
A25: 13 | B25: Lifecycle | C25: Monitoring | D25: Is there performance / quality monitoring during operation? | F25: =IF(E21="Low (1)",1,IF(E21="Medium (2)",2,IF(E21="High (3)",3,"")))
A26: 14 | B26: Lifecycle | C26: Incident response | D26: Is there an AI incident response mechanism / response plan? | F26: =IF(E22="Low (1)",1,IF(E22="Medium (2)",2,IF(E22="High (3)",3,"")))
A27: 15 | B27: Lifecycle | C27: Data drift | D27: Can it detect drift / quality changes over time? | F27: =IF(E23="Low (1)",1,IF(E23="Medium (2)",2,IF(E23="High (3)",3,"")))
A28: 16 | B28: Governance | C28: Human oversight | D28: Is there human-in-the-loop / final accountability? | F28: =IF(E24="Low (1)",1,IF(E24="Medium (2)",2,IF(E24="High (3)",3,""))) | G28: CRITICAL
A29: 17 | B29: Governance | C29: Roles & responsibility | D29: Are roles, responsibilities, and owners clearly defined? | F29: =IF(E25="Low (1)",1,IF(E25="Medium (2)",2,IF(E25="High (3)",3,"")))
A30: 18 | B30: Governance | C30: Documentation | D30: Is there sufficient documentation, evidence, and audit trail? | F30: =IF(E26="Low (1)",1,IF(E26="Medium (2)",2,IF(E26="High (3)",3,"")))
A31: 19 | B31: Business | C31: Use case clarity | D31: Is the use case clearly defined and specific? | F31: =IF(E27="Low (1)",1,IF(E27="Medium (2)",2,IF(E27="High (3)",3,"")))
A32: 20 | B32: Business | C32: Business value | D32: Is there clear benefit / ROI for BUV? | F32: =IF(E28="Low (1)",1,IF(E28="Medium (2)",2,IF(E28="High (3)",3,"")))
A33: 21 | B33: Business | C33: Scalability | D33: Can it scale to multiple departments / university-wide? | F33: =IF(E29="Low (1)",1,IF(E29="Medium (2)",2,IF(E29="High (3)",3,"")))
A34: 22 | B34: Vendor | C34: Vendor maturity | D34: Does the vendor have sufficient maturity/certification? | F34: =IF(E30="Low (1)",1,IF(E30="Medium (2)",2,IF(E30="High (3)",3,"")))
A35: 23 | B35: Vendor | C35: Data ownership | D35: Are data ownership terms clear? | F35: =IF(E31="Low (1)",1,IF(E31="Medium (2)",2,IF(E31="High (3)",3,"")))
A36: 24 | B36: Vendor | C36: Exit strategy | D36: Is there an exit plan / portability / avoid lock-in? | F36: =IF(E32="Low (1)",1,IF(E32="Medium (2)",2,IF(E32="High (3)",3,"")))
A38: ACADEMIC CRITERIA (V1.1)
A39: 25 | B39: Academic Value | C39: Pedagogical Value | D39: Does the tool demonstrably improve teaching, learning, or research outcomes? Evidence of pedagogical benefit required. | G39: Med
A40: 26 | B40: Academic Value | C40: Research Enablement | D40: Does the tool support Safe Harbor use cases (patent preparation, manuscript drafting, NDA consulting) or other research infrastructure needs? | G40: Low
A41: 27 | B41: Academic Value | C41: Faculty Adoption & Demand | D41: Is there clear, documented demand from academic staff? Has the tool been requested or endorsed by an academic unit? | G41: Low
A42: 28 | B42: Academic Strategy | C42: Alignment with BUV Strategic Academic Goals | D42: Does the tool align with BUV's published academic strategy, research priorities, and international partnership goals? | G42: Med
A43: 29 | B43: Academic Freedom | C43: Academic Freedom & Open Inquiry Impact | D43: Does the tool impose any restriction on academic inquiry, intellectual exploration, or staff autonomy in research or teaching? | G43: CRITICAL
...

Sheet Guide
A1: Scoring Guide
A3: Score level | B3: Meaning
A4: Low (1) | B4: Low risk, well controlled, suitable for adoption.
A5: Medium (2) | B5: Medium risk, can be used but requires control/limited scope of use.
A6: High (3) | B6: High risk, should not approve immediately; needs deep review or reject.
A7: APPROVE | B7: Total score ≤ 38 and no Critical High. | V1.1: Joint sign-off required (ICT Director + AI Governance Committee Chair).
A8: CONDITIONAL | B8: Total score 39–52 or 1 Critical High or risks requiring mitigation measures. | V1.1: Conditions must be agreed by ICT and the Committee jointly.
A9: REJECT | B9: Total score > 52, or ≥ 4 High criteria, or ≥ 2 Critical High. | V1.1: Rejection may be appealed to the AI Governance Committee; on disagreement with ICT, escalated to the Joint Review Board (Guideline §9).
A11: V1.1 JOINT DECISION AUTHORITY
A12: Dual Sign-Off | B12: All APPROVE / CONDITIONAL / REJECT decisions require the joint signature of the ICT Director (technical/security) and the AI Governance Committee Chair (academic/governance). A single signature is not sufficient.
A13: Escalation | B13: Where ICT and the Committee cannot agree, the matter is referred to the Joint Review Board (per BUV AI Usage Guideline V2.1, Section 9) for binding determination within 15 working days.
A14: Default-Approval | B14: Where the ICT Security Assessment and the Academic Committee Review have not been completed within 15 working days of a complete request, the requesting department may refer the matter to the JRB. Pending JRB determination, the tool is provisionally approved for Green-tier work only.
A15: Academic Criteria | B15: Academic criteria (rows 25-29 of the Evaluation sheet) are scored by the AI Governance Committee or its designee, not by ICT. ICT scores rows 1-24 only.
A16: Critical High Override | B16: If a Critical High item is academic in nature (e.g., academic freedom impact), the AI Governance Committee can override the ICT technical recommendation by escalating to the JRB.

Sheet Dashboard
A1: Summary Dashboard – ICT / DPO
A3: Metric | B3: Value | D3: Distribution | E3: Count
A4: Total criteria | B4: 29 | D4: Low (1) | E4: =COUNTIF(Evaluation!E9:E32,"Low (1)")
A5: Total score | B5: =Evaluation!C10 | D5: Medium (2) | E5: =COUNTIF(Evaluation!E9:E32,"Medium (2)")
A6: Average score | B6: =ROUND(AVERAGE(Evaluation!F9:F32),2) | D6: High (3) | E6: =COUNTIF(Evaluation!E9:E32,"High (3)")
A7: High count | B7: =Evaluation!E10
A8: Critical High count | B8: =Evaluation!G10 -> 0
A9: Conclusion | B9: JOINT (ICT + AI Governance Committee)
A12: V1.1 AMENDMENT NOTE
A13: The Conclusion on the Evaluation sheet is no longer the sole province of ICT. Both the ICT Director (technical/security) and the AI Governance Committee Chair (academic/governance) must sign before the institutional APPROVE / CONDITIONAL / REJECT decision is final. The Evaluation sheet now includes 5 additional academic criteria (rows 25-29) that are scored by the Committee, not ICT. Total criteria count updated from 24 to 29. See Guide sheet "V1.1 JOINT DECISION AUTHORITY" section for full rules.
